Error Log File - Scenario: db_startup_failure
Generated at: 2025-09-07T21:44:28.032346
Crash ID: a3867d24-c22d-4e37-8263-8adb632b83f3
==================================================

2025-09-07T16:14:26.534Z BOOT INFO starting FastAPI app import=backend.main
2025-09-07T16:14:26.629Z DB ERROR Database connection failed (Attempts: 3/3)
Traceback (most recent call last):
  File "/Users/hariskumargs/Documents/Personal/TiDB-Hackathon/sample-ecommerce-app/backend/main.py", line 7, in <module>
    from core.middleware import start_up_db
  File "/Users/hariskumargs/Documents/Personal/TiDB-Hackathon/sample-ecommerce-app/backend/core/middleware.py", line 48, in start_up_db
    raise DatabaseConnectionError
core.errors.DatabaseConnectionError
